Workbook

Sheet survey
A1: ID | B1: Start time | C1: Completion time | D1: Email | E1: Name | F1: Last modified time | G1: Your full name (Firstname Lastname): | H1: Your email address (will be used only if follow-up clarifications would be needed): | I1: Your organization: | J1: For the model/scenarios of which work package (WP), are you filling out this survey? | K1: The name of the modeling tool for which you fill out the survey: | L1: What is the main category of the model? | M1: What option describes your modeling approach best? | N1: What geographical scope presents your model best? | O1: What is the spatial resolution of your model concerning the EU region? | P1: What level(s) of the electricity network is represented in your model? | Q1: How are cross-border transmission lines between EU countries represented in your model? | R1: How the planning foresight is treated in your model: | S1: What time intervals are considered in the model horizon? (Please tick all that apply) | T1: What planning/modeling horizon is used in your analysis? | U1: How is the sub-annual temporal resolution represented in your model? | V1: If you answered "Representative time slices" or "Other", please explain. For example, the method of sampling/clustering and/or the length of time slices. | W1: Is the chronology of (sub-annual) time slices preserved in your modeling work? | X1: Is the joint variability of supply and demand resources in each sub-annual time slice captured in your model? This means, e.g., the timeseries of wind, solar PV, and demand are all concurrent with... | Y1: How are short-term operational events represented in your model? Short-term decisions are in the scale of hours to a few days including generator scheduling, ramping rates, flexibility requirement... | Z1: If short-term decisions are not represented explicitly in your model, how is the relevant parametrization done? Check all relevant answers. | AA1: How are short-term decisions linked to long-term infrastructure planning and investment decisions in your model? Long-term decisions refer to multi-decadal decisions such as investment in power pl... | AB1: Is the weather uncertainty in multiple years included in your model parameters? | AC1: What future uncertainties are considered when representing sub-annual temporal variability in your model parameters? Here, we refer to those events not driven by socioeconomic developments or cost... | AD1: What is the level of granularity in representing technologies in your model? | AE1: Which of the following demand and supply-side sectors are included in your model? Please choose all that apply. | AF1: How electricity demand is represented in your model? | AG1: If your answer was "Other", please explain: | AH1: Which VRE sources are represented in your model? Please choose all that apply. | AI1: What aspect(s) of VRE is represented in the model? Please choose all that apply. | AJ1: What VRE integration costs or requirements are modeled explicitly, i.e., depending on the capacity/generation of VRE? Please choose all that apply. | AK1: Please explain the representation of VRE integration in your model, if it cannot be described by the options above or in case of ticking "Other". | AL1: Can load be technically met only by VRE in a given (sub-annual) time slice in your model? | AM1: What constraints limit the penetration of VRE in your model? Please choose all that apply. | AN1: Please explain any additional points considering the constraints in your model that would limit the penetration of VRE, e.g., to meet 100% of the load. | AO1: How the mismatch between electricity from VRE and load can be balanced in your model? Please choose all that apply. | AP1: Have you explicitly modeled one or several electricity storage technologies in your model? | AQ1: What forms of storage duration are considered in your model? The storage duration can be attributed to the choice of technology, e.g., batteries for the short and pumped hydro for the long term. P... | AR1: What storage technology categories are represented in your model? Please choose all that apply. | AS1: Do you represent various storage technologies within a category (e.g., different battery chemistries) in your model? | AT1: Please list technologies represented within each category mentioned above, only for applicable categories (e.g., Batteries: Li-ion, Lead-acid). | AU1: What technical characteristics of electricity storage are modeled explicitly? Please choose all that apply. | AV1: If applicable, please list other characteristics of storage represented in your model that are not listed above: | AW1: What economic characteristics of electricity storage are modeled explicitly? (O&M = operation and maintenance). Please choose all that apply. | AX1: Are the costs of the power conversion system (PCS) and the storage reservoir/container represented separately in your model? | AY1: Which service categories are relevant for storage technologies in your model? Please tick all that apply. | AZ1: Where are storage technologies represented in your model? Please tick all that apply. | BA1: Which energy-related storage services are represented in your model? Please tick all that apply. | BB1: Which power capacity-related storage services are represented in your model? Please tick all that apply. | BC1: Which T&D-related storage services are represented in your model? Please tick all that apply. | BD1: Which storage services concerning VRE are represented in your model? Please tick all that apply. | BE1: Please briefly explain the way energy storage can support the integration of VRE in your model, if not fully covered through the questions asked above. | BF1: Which one of the following parameters affects the deployment of energy storage technologies in your model positively? Please tick all that apply. | BG1: Please explain if the answer included "Other" and/or if you would like to add explanations. | BH1: How is the system integration of electricity storage constrained in your model? Please tick all that apply. | BI1: Can storage technologies contribute to multiple services in your model? This functionality known as "revenue stacking" or "aggregation of benefits" allows a storage provider to offer energy-, cap... | BJ1: How is the ownership of storage and its revenues represented in your model? | BK1: Please add any points related to the integration of energy storage in your model that you believe are not covered in the previous questions. | BL1: Are energy storage technologies and their parameters treated differently based on the modeled scenario in your work? (e.g., more optimistic energy storage cost assumptions in electrification scena... | BM1: If relevant, please explain your scenario-specific assumptions concerning storage technologies briefly. For example, do you consider different storage performance/cost parameters or storage integr... | BN1: (Only for the teams in the ECEMF project) We need additional variables for conducting the storage analysis. Please tick all Priority 1 variables that you can report for your scenarios.
A2: 2 | B2: 45552.525 | C2: 45552.537 | D2: anonymous | G2: Panagiotis Fragkos | H2: panagiotis.fragkos@ricardo.com | I2: E3Modelling | J2: WP1 (Task 1.3); | K2: PROMETHEUS | L2: Integrated assessment model | M2: Market simulation | N2: Global | O2: EU divided in 2-3 subregions | P2: Coarse copperplate (multiple countries in one modeling node) | Q2: Not modeled | R2: Myopic foresight (short sighted) | S2: Yearly; | T2: ~2050 (mid century) | U2: Yearly (No sub-annual time slices) | Y2: Short-term events are represented implicitly, e.g., as a cost or other proxy. | Z2: Using data from various empirical or model-based studies; | AA2: Short-term decisions are represented using proxies and/or in a stylized format as part of long-term decisionmaking | AB2: Yes, using varying input data (or sensitivity analysis) | AC2: Climate impact on the supply side;Climate impact on the demand side; | AD2: Technologies by input fuel type (e.g., all gas power plant types aggregated together) | AE2: Buildings;Fossil fuel supply ;Industry sector;Renewable-based fuels and derivatives (e.g., green hydrogen);Power (supply) sector;Transport sector; | AF2: Demand is modeled endogenously | AH2: Concentrated solar power (CSP) (w/o storage);Onshore wind;Offshore wind;Solar photovoltaic (PV) (general); | AI2: Direct costs (capital, O&M, etc.);Indirect costs (integration costs);Resource potential;Technical characteristics (efficiency, capacity factor, etc.) ;Weather dependency (varying output in different time scales within a year); | AJ2: Grid management/contingency costs;Additional ancillary/balancing services costs (economic);Reduced capacity factor of non-VRE; | AL2: Yes (but partly has to be with stored or firmed VRE) | AM2: Integration cost (economic/implicit);Resource potential;Maximum share of VRE (either from generation, load, input to T&D, etc.); | AO2: Electricity storage;Power to hydrogen (electrolyzers); | AP2: Yes | AQ2: Short-term (hours to a few days);Long-term (months to seasons); | AR2: Storage is represented as a generic or homogenous asset w/o specific technology types.; | AS2: No | AU2: Capacity factor (max or nominal);Charge capacity (MW) (if it can be different from discharge capacity);Lifetime (in years);Power capacity (MW) (used for both charge and discharge); | AW2: Capital cost;Variable O&M cost;Fixed O&M cost;End-of-lifetime cost or resale; | AX2: No (PCS and reservoir are treated with one cost value) | AY2: Renewable energy integration (e.g., curtailment reduction);Energy-related (e.g., peak shaving); | AZ2: Storage is represented generically (no location specific); | BA2: Energy-related services are modeled collectively.; | BB2: Capacity-related services are modeled collectively.; | BC2: Not relevant; | BD2: Curtailment reduction;Energy time-shifting; | BF2: Cost competetiveness (incl. capital cost, O&M cost, levelized cost, etc.) compared to other alternatives;Rapid cost learning, i.e., the decline of storage cost in future;The increasing share of VRE in the system (e.g., as % of annual load or generation);The value of capacity services of storage;Increased variability in the pattern of VRE within a year; | BH2: Storage capacity/activity is dependent to that of VRE (i.e., no VRE --> no storage).; | BI2: Not relevant | BJ2: Not relevant | BL2: Yes | BM2: yes | BN2: Capacity of storage (GWh);Capital cost of storage technologies (EUR/GW or EUR/GWh);
A3: 3 | B3: 45552.552 | C3: 45552.637 | D3: anonymous | G3: Harmen Sytze de Boer | H3: boerdhs@pbl.nl | I3: PBL | J3: WP1 (Task 1.3);WP3;WP5; | K3: IMAGE | L3: Integrated assessment model | M3: Investment and capacity exapnsion planning | N3: Global | O3: EU divided in 2-3 subregions | P3: Coarse copperplate (multiple countries in one modeling node) | Q3: Using proxies or stylized methods | R3: Recursive dynamic (feedback loop) | S3: Yearly; | T3: ~2100 (full century) | U3: Multi-hourly | W3: No | X3: Yes, although the demand pattern is historic and not based on endogenous demand sector developments | Y3: A few extreme short-term events are represented explicitly (e.g., seasonal peak load and zero supply from renewables). | Z3: Using data from various empirical or model-based studies;We use the RLDC dataset developed by PIK during the ADVANCE project (Ueckerdt et al., 2016); | AA3: Short-term decisions are represented using proxies and/or in a stylized format as part of long-term decisionmaking | AB3: Data of one representative year based on irradiation and wind speed data for 1984–2005 | AC3: None of the above or not relevant; | AD3: Scale-free technology types (e.g., different gas power plant types aggregated separately) | AE3: Buildings;Fossil fuel supply ;Heat supply (including district heating/cooling);Industry sector;Renewable-based fuels and derivatives (e.g., green hydrogen);Power (supply) sector;Transport sector; | AF3: Depends on the sector. Some are modelled in much detail (transport, industry), while other are more aggregated | AG3: Depends on the sector. Some are modelled in much detail (transport, industry), while other are more aggregated | AH3: Concentrated solar power (CSP) (w/o storage);Onshore wind;Offshore wind;Run-of-the-river hydropower (w/o storage);Solar photovoltaic (PV) (general);Solar photovoltaic (PV) (rooftop);Solar photovoltaic (PV) (utility);Tidal or marine energy; | AI3: Capacity value (contribution to power adequacy);Curtailment;Direct costs (capital, O&M, etc.);Indirect costs (integration costs);Resource potential;Technical characteristics (efficiency, capacity factor, etc.) ;Weather dependency (varying output in different time scales within a year); | AJ3: Curtailment cost (i.e., cost of handling excess electricity or negative prices);Grid expansion or fortification needs;Reduced capacity factor of non-VRE;Storage requirements for energy time-shifting; | AL3: Yes (no need for generation from non-VRE or discharge from storage) | AM3: Integration requirements (technical/explicit, e.g., grid expansion and/or storage scale-up);Resource potential;Integration cost (economic/implicit); | AN3: At some point, the load factor of any marginal solar/wind capacity gets quite small due to curtailments. Also, VRE can be backup for VRE. However, the firm capacity of marginal solar/wind capacity also gets quite low (increasing backup costs) | AO3: Curtailment of VRE;Electricity storage;Flexible electricity generation from thermal power (e.g., biomass, coal, gas) with or w/o CCS;Flexible electricity generation from hydropower;Flexible electricity generation from nuclear power;Power to hydrogen (electrolyzers); | AP3: No, storage is modeled as cost or other proxy | AQ3: Short-term (hours to a few days);Medium-term (a few weeks);Long-term (months to seasons); | AR3: Flow batteries (e.g., Vanadium-Redox);Storage in the form of hydrogen; | AS3: No | AU3: Our flow battery storage is included in the RLDC dataset we use. For certain shares of wind/solar, the dataset provides us with required storage capacity (MW/MWh). Round trip efficiencies are included in the dataset. Hydrogen can also be used as a way of storing electricity (although the hydrogen is not necessarily used again in het electricity sector); | AW3: Capital cost; | AX3: No (PCS and reservoir are treated with one cost value) | AY3: Renewable energy integration (e.g., curtailment reduction);Power capacity-related (e.g., capacity firming);Energy-related (e.g., peak shaving); | AZ3: At the generation side (utility VRE);At the generation side (central power plants); | BA3: Peak shaving (e.g., daily, seasonal); | BB3: Capacity firming of non-VRE (e.g., day/night smoothing of nuclear power); | BC3: Grid services are modeled collectively.; | BD3: Curtailment reduction;Capacity firming (increasing capacity value of VRE); | BF3: The increasing share of VRE in the system (e.g., as % of annual load or generation); | BH3: The RLDC dataset we use includes required storage capacity for different shares of VRE; | BI3: No, the contribution of storage is only allowed to certain services (e.g., either to energy- or capacity-related services). | BJ3: Storage contributes to the system-level benefits. | BL3: Yes | BM3: The RLDC dataset (including storage) is available for various levels of VRE integration constraints (strict, normal, relaxed) | BN3: Capacity of storage (GWh);Electricity supplied/discharged by storage technologies (EJ/yr);Power capacity of electricity storage (GW);Power capacity of hydrogen electrolyzer (GW);
A4: 5 | B4: 45558.575 | C4: 45558.621 | D4: anonymous | G4: Igor Tatarewicz | H4: igor.tatarewicz@kobize.pl | I4: KOBIZE/CAKE | J4: WP1 (Task 1.3);WP5; | K4: MEESA | L4: Power system model | M4: Investment and capacity exapnsion planning | N4: Europe (e.g., EU27 & UK & EEA) | O4: Multiple-country (~1-4 EU countries in each model region) | P4: Coarse copperplate (multiple countries in one modeling node) | Q4: Using a backbone or star model (nodes connected via a central grid) | R4: Perfect foresight | S4: 2- to 5-yearly; | T4: ~2050 (mid century) | U4: Representative time slices (sampled or clustered) | V4: 18 or 72 time slices - two seasons, 3 types of day per season, 3 day periods - (day, night, peak in 18 TS) or 12 2-hours periods per day (in 72 TS) | W4: Yes | X4: Yes, for all time slices | Y4: A few extreme short-term events are represented explicitly (e.g., seasonal peak load and zero supply from renewables). | Z4: Using data from various empirical or model-based studies; | AA4: Short- and long-term decisions are co-optimized in an integrated way. | AB4: Yes, using varying input data (or sensitivity analysis) | AC4: Operational uncertainty (e.g., generator outages or demand or renewable energy forecast errors); | AD4: Technologies by input fuel type (e.g., all gas power plant types aggregated together) | AE4: Fossil fuel supply ;Heat supply (including district heating/cooling);Renewable-based fuels and derivatives (e.g., green hydrogen);Power (supply) sector; | AF4: Static demand (no response to supply cost) | AH4: Onshore wind;Offshore wind;Run-of-the-river hydropower (w/o storage);Solar photovoltaic (PV) (rooftop);Solar photovoltaic (PV) (utility); | AI4: Capacity value (contribution to power adequacy);Direct costs (capital, O&M, etc.);Technical characteristics (efficiency, capacity factor, etc.) ;Weather dependency (varying output in different time scales within a year);Resource potential; | AJ4: Additional ancillary/balancing services costs (economic); | AK4: increasing variable VRE cost as the use of a given technology increases, simulating additional network/balancing costs | AL4: Yes (no need for generation from non-VRE or discharge from storage) | AM4: Resource potential;Minimum share of non-VRE technologies (e.g., stabilizing share, firm capacity, etc.);Integration requirements (technical/explicit, e.g., grid expansion and/or storage scale-up);Temporal or spatial mismatch between VRE and load; | AO4: Electricity storage;Flexible electricity generation from thermal power (e.g., biomass, coal, gas) with or w/o CCS;Flexible electricity generation from nuclear power;Power to hydrogen (electrolyzers);Demand response in transport (e.g., smart charging of EVs);Demand response (generic, no sector-specific);Curtailment of VRE;Curtailment of load (unserved energy);Electricity export/import (grid connection);Power to heat (w/ or w/o storage); | AP4: Yes | AQ4: Short-term (hours to a few days);Medium-term (a few weeks); | AR4: Pumped hydro storage;Secondary electorchemical batteries (e.g., Li-ion, etc.);hydrogen storage; | AS4: No | AU4: Lifetime (in years);Power capacity (MW) (used for both charge and discharge);Storage content balance (equal storage content at the beginning and end of a model year/period);Duration of discharge or energy-to-power ratio (h);Charge capacity (MW) (if it can be different from discharge capacity);Discharging efficiency;Discharge capacity (MW) (if it can be different from charge capacity);Charging efficiency; | AW4: Capital cost;Variable O&M cost;Fixed O&M cost; | AX4: Yes (for some or all technologies) | AY4: Energy-related (e.g., peak shaving);Power capacity-related (e.g., capacity firming);Renewable energy integration (e.g., curtailment reduction); | AZ4: Power transmission level;Power distribution level;End-use side (buildings); | BA4: Peak shaving (e.g., daily, seasonal);Energy time shifting (arbitrage);Increasing self-consumption at the end use side; | BB4: Capacity-related services are modeled collectively.; | BC4: Transmission and distribution services are represented separately.; | BD4: VRE-related services of storage are modeled in an aggregated way (i.e., no individual representation of services).; | BF4: Cost competetiveness (incl. capital cost, O&M cost, levelized cost, etc.) compared to other alternatives;Rapid cost learning, i.e., the decline of storage cost in future;The increasing share of VRE in the system (e.g., as % of annual load or generation);Increased volatility in the pattern of electric load within a year;Increased variability in the pattern of VRE within a year; | BH4: Storage is constrained by build-up, technological learning, and/or market-penetration growth rates (i.e., dynamic constraints dependent on storage deployment).;(Some or all) storage technologies are constrained by available sites, resource potential, material availability, etc. (i.e., static constraints not necessarily dependent on storage deployment); | BI4: No, the contribution of storage is only allowed to certain services (e.g., either to energy- or capacity-related services). | BJ4: Storage contributes to the system-level benefits. | BL4: No, storage parameters were kept consistently across scenarios. | BM4: - | BN4: Capacity of storage (GWh);Capital cost of storage technologies (EUR/GW or EUR/GWh);Duration of charge/discharge (h);Efficiency of storage technologies (as % or lost energy (EJ/yr));Electricity supplied/discharged by storage technologies (EJ/yr);Lifetime of storage technologies (year);Net electricity trade (import/export) (EJ/yr);Power capacity of electricity storage (GW);Power capacity of hydrogen electrolyzer (GW);
A5: 7 | B5: 45561.504 | C5: 45561.509 | D5: anonymous | G5: Johannes Emmerling | H5: johannes.emmerling@cmcc.it | I5: CMCC | J5: WP3;WP5;WP1 (Task 1.3); | K5: WITCH | L5: Integrated assessment model | M5: Macro-economic modeling | N5: Global | O5: EU- or European level (one model region) | P5: Coarse copperplate (multiple countries in one modeling node) | Q5: Not modeled | R5: Perfect foresight | S5: 2- to 5-yearly; | T5: ~2100 (full century) | U5: Yearly (No sub-annual time slices) | Y5: Short-term events are represented implicitly, e.g., as a cost or other proxy. | Z5: Using data from various empirical or model-based studies; | AA5: Short-term decisions are not relevant to the modeling scope. | AB5: No | AC5: Climate impact on the supply side;Climate impact on the demand side; | AD5: Technologies by input fuel type (e.g., all gas power plant types aggregated together) | AE5: Buildings;Power (supply) sector;Transport sector; | AF5: Static demand (no response to supply cost) | AH5: Concentrated solar power (CSP) (w/o storage);Onshore wind;Offshore wind;Solar photovoltaic (PV) (general); | AI5: Capacity value (contribution to power adequacy);Curtailment;Direct costs (capital, O&M, etc.);Indirect costs (integration costs);Resource potential; | AJ5: Curtailment cost (i.e., cost of handling excess electricity or negative prices);Grid expansion or fortification needs; | AL5: No (there must be a level of non-VRE generation) | AM5: Maximum share of VRE (either from generation, load, input to T&D, etc.); | AO5: Curtailment of VRE;Electricity storage; | AP5: No, storage is modeled as cost or other proxy | AQ5: Long-term (months to seasons);Medium-term (a few weeks); | AR5: Compressed air-based technologies;Pumped hydro storage; | AS5: No | AU5: Capacity factor (max or nominal);Charge capacity (MW) (if it can be different from discharge capacity); | AW5: Capital cost;Variable O&M cost; | AX5: No (PCS and reservoir are treated with one cost value) | AY5: Power capacity-related (e.g., capacity firming); | AZ5: At the generation side (central power plants); | BA5: Energy-related services are modeled collectively.; | BB5: Back-up capacity (once or a few times a year);Capacity firming of non-VRE (e.g., day/night smoothing of nuclear power); | BC5: Not relevant; | BD5: Curtailment reduction; | BF5: Cost competetiveness (incl. capital cost, O&M cost, levelized cost, etc.) compared to other alternatives;Rapid cost learning, i.e., the decline of storage cost in future;The increasing share of VRE in the system (e.g., as % of annual load or generation); | BH5: Storage capacity/activity is dependent to that of VRE (i.e., no VRE --> no storage).;Storage capacity/activity is capped to a certain share of another process, such as generation, flexibility, T&D, load, etc. (e.g., max 40% of load can be met by storage discharge); | BI5: No, the contribution of storage is only allowed to certain services (e.g., either to energy- or capacity-related services). | BJ5: Storage contributes to the system-level benefits. | BL5: No, storage parameters were kept consistently across scenarios. | BM5: for now we didnt change storage parameters. | BN5: Capacity of storage (GWh);Lifetime of storage technologies (year);Power capacity of electricity storage (GW);
A6: 8 | B6: 45562.449 | C6: 45562.487 | D6: anonymous | G6: Amir Fattahi | H6: amir.fattahi@tno.nl | I6: TNO | J6: WP1 (Task 1.3); | K6: TIAM-ECN | L6: Integrated assessment model | M6: Investment and capacity exapnsion planning | N6: Global | O6: EU divided in 2-3 subregions | P6: Coarse copperplate (multiple countries in one modeling node) | Q6: cross-border lines are modelled between two subregions of EU (EastEU and WestEU) through an aggregated proxy. | R6: Perfect foresight | S6: 2- to 5-yearly;10-yearly and/or longer; | T6: ~2100 (full century) | U6: Seasonal (2-4 time slices per model period) | W6: No | X6: Not relevant (e.g., no temporal representation) | Y6: Only for solar and wind generation, we represent short-term events implicitly as an additional flexibility requirement costs. | Z6: Bidirectional soft-linking to a detailed operational and dispatch model;Using data from various empirical or model-based studies;We are doing a bidirectional soft-linking with a detailed power system model in WP3.2. It is a work in progress.. ; | AA6: Short- and long-term decisions are co-optimized in an integrated way. | AB6: No | AC6: None of the above or not relevant; | AD6: Scale-free technology types (e.g., different gas power plant types aggregated separately) | AE6: Buildings;Fossil fuel supply ;Heat supply (including district heating/cooling);Industry sector;Renewable-based fuels and derivatives (e.g., green hydrogen);Power (supply) sector;Transport sector; | AF6: Demand is modeled endogenously | AH6: Concentrated solar power (CSP) (w/o storage);Onshore wind;Offshore wind;Run-of-the-river hydropower (w/o storage);Solar photovoltaic (PV) (general); | AI6: Direct costs (capital, O&M, etc.);Indirect costs (integration costs);Technical characteristics (efficiency, capacity factor, etc.) ;Resource potential;Weather dependency (varying output in different time scales within a year); | AJ6: Additional O&M cost of non-VRE; | AL6: Yes (no need for generation from non-VRE or discharge from storage) | AM6: Integration cost (economic/implicit);Resource potential;Temporal or spatial mismatch between VRE and load; | AO6: Curtailment of VRE;Flexible electricity generation from thermal power (e.g., biomass, coal, gas) with or w/o CCS;Flexible electricity generation from nuclear power;Power to hydrogen (electrolyzers);Power to heat (w/ or w/o storage);Power to synfuels (other than hydrogen);Electricity export/import (grid connection); | AP6: No | AQ6: Storage duration does not play a role (e.g., storage is modeled generically); | AR6: No storage is modelled in TIAM-ECN. I have to give an answer to Q35 to continue the survey. ; | AS6: No | AU6: No storage is modelled in TIAM-ECN; | AV6: No storage is modelled in TIAM-ECN. | AW6: No storage is modelled in TIAM-ECN; | AX6: Cost of storage is not relevant or represented | AY6: Ancillary services (e.g., frequency regulation); | AZ6: Not relevant; | BA6: No storage is modelled in TIAM-ECN. Please ignore Q42 answer. I had to tick a box to continue the survey. ; | BB6: No storage is modelled in TIAM-ECN; | BC6: Not relevant; | BD6: No storage is modelled in TIAM-ECN; | BF6: Not relevant; | BH6: Not relevant; | BI6: Not relevant | BJ6: Not relevant | BL6: No, storage parameters were kept consistently across scenarios. | BM6: No storage is modelled in TIAM-ECN. | BN6: Power capacity of hydrogen electrolyzer (GW);Net electricity trade (import/export) (EJ/yr);
A7: 10 | B7: 45565.722 | C7: 45565.883 | D7: anonymous | G7: Robert Pietzcker | H7: pietzcker@pik-potsdam.de | I7: Potsdam Institute for Climate Impact Research | J7: WP1 (Task 1.3); | K7: REMIND | L7: Integrated assessment model | M7: Hybrid: coupling an investment and capacity expansion energy system with a Ramsey growth model | N7: Global | O7: Multiple-country (~1-4 EU countries in each model region) | P7: Coarse copperplate (multiple countries in one modeling node) | Q7: not explicitly modeled, but generalized transmission expansion and pooling effects across EU regions are included | R7: Perfect foresight | S7: 2- to 5-yearly; | T7: ~2100 (full century) | U7: Not explicitly, but the effects on VRE integration/storage/transmission build-out are represented in an aggregate way | V7: Not explicitly, but the effects on VRE integration/storage/transmission build-out are represented in an aggregate way, parameterized to reflect results from more detailed (hourly) models | W7: Other | X7: Not relevant (e.g., no temporal representation) | Y7: Short-term events are represented implicitly, e.g., as a cost or other proxy. | Z7: Using data from various empirical or model-based studies; | AA7: Short-term decisions are represented using proxies and/or in a stylized format as part of long-term decisionmaking | AB7: No | AC7: None of the above or not relevant; | AD7: Scale-free technology types (e.g., different gas power plant types aggregated separately) | AE7: Buildings;Fossil fuel supply ;Heat supply (including district heating/cooling);Industry sector;Renewable-based fuels and derivatives (e.g., green hydrogen);Power (supply) sector;Transport sector; | AF7: Demand is modeled endogenously | AH7: Concentrated solar power (CSP) (w/o storage);Onshore wind;Offshore wind;Run-of-the-river hydropower (w/o storage);Solar photovoltaic (PV) (general); | AI7: Resource potential;Indirect costs (integration costs);Direct costs (capital, O&M, etc.);Curtailment;Technical characteristics (efficiency, capacity factor, etc.) ; | AJ7: Curtailment cost (i.e., cost of handling excess electricity or negative prices);Grid expansion or fortification needs;Storage requirements for energy time-shifting; | AL7: Yes (but partly has to be with stored or firmed VRE) | AM7: Integration cost (economic/implicit);Minimum share of non-VRE technologies (e.g., stabilizing share, firm capacity, etc.);Integration requirements (technical/explicit, e.g., grid expansion and/or storage scale-up);Resource potential; | AN7: on question 31: what is "firmed VRE"? in our model, there has to be some storage discharge and there has to be some electricity generation from either gas peaking plants or hydrogen peaking plants - in ambitious mitigation scenarios, the model then only uses hydrogen peaking plants from electrolysis-hydrogen. is this "stored electricity", or is it "a level on non-VRE-generation"? | AO7: not explicitly modeled, but many of these options are contained in the models that were used to parameterize the integration constraints/storage/grid/curtailment; | AP7: Yes | AQ7: Storage duration does not play a role (e.g., storage is modeled generically); | AR7: Secondary electorchemical batteries (e.g., Li-ion, etc.);electrolyzers + h2 turbines; | AS7: No | AU7: Duration of discharge or energy-to-power ratio (h);Round-trip efficiency;Storage reservoir size (MWh);Discharge capacity (MW) (if it can be different from charge capacity); | AW7: Capital cost;Fixed O&M cost; | AX7: No (PCS and reservoir are treated with one cost value) | AY7: Renewable energy integration (e.g., curtailment reduction); | AZ7: Storage is represented generically (no location specific); | BA7: see below - not explicitly modeled; | BB7: see below - not explicitly modeled; | BC7: Not relevant; | BD7: VRE-related services of storage are modeled in an aggregated way (i.e., no individual representation of services).; | BE7: Storage deployment is modeled as a requirement from VRE deployment, with the specific storage requirements per kWh of VRE electricity increasing linearly with the share of VRE. (so in total, storage requirements increase roughly with the square of VRE share) | BF7: The increasing share of VRE in the system (e.g., as % of annual load or generation); | BH7: Storage capacity/activity is dependent to that of VRE (i.e., no VRE --> no storage).;Storage is constrained by build-up, technological learning, and/or market-penetration growth rates (i.e., dynamic constraints dependent on storage deployment).; | BI7: as said above, storage is directly hard-linked to VRE deployment | BJ7: Not relevant | BL7: Yes | BM7: yes, we decrease the storage capacity requirements at a given VRE share, as we assume more demand side management, better use of vehicle-to-grid, better pooling etc. | BN7: Capacity of storage (GWh);Capital cost of storage technologies (EUR/GW or EUR/GWh);Duration of charge/discharge (h);Power capacity of electricity storage (GW);Power capacity of hydrogen electrolyzer (GW);
A8: 11 | B8: 45570.865 | C8: 45570.881 | D8: anonymous | G8: Behnam Zakeri | H8: zakeri@iiasa.ac.at | I8: IIASA | J8: WP1 (Task 1.3);WP5; | K8: MESSAGEix-GLOBIOM | L8: Integrated assessment model | M8: Investment and capacity exapnsion planning | N8: Global | O8: EU divided in 2-3 subregions | P8: Coarse copperplate (multiple countries in one modeling node) | Q8: Using proxies or stylized methods | R8: Perfect foresight | S8: 2- to 5-yearly;10-yearly and/or longer; | T8: ~2100 (full century) | U8: Yearly (No sub-annual time slices) | Y8: Short-term events are represented implicitly, e.g., as a cost or other proxy. | Z8: Using data from various empirical or model-based studies;Using data from a detailed operational and dispatch model (unidirectional soft-linking); | AA8: Short-term decisions are represented using proxies and/or in a stylized format as part of long-term decisionmaking | AB8: Applying peak load factors to cover grid contingencies and uncertainties in load | AC8: None of the above or not relevant; | AD8: Scale-free technology types (e.g., different gas power plant types aggregated separately) | AE8: Buildings;Fossil fuel supply ;Heat supply (including district heating/cooling);Industry sector;Renewable-based fuels and derivatives (e.g., green hydrogen);Power (supply) sector;Transport sector; | AF8: Elastic demand (responsive to supply cost) | AH8: Concentrated solar power (CSP) (w/o storage);Onshore wind;Offshore wind;Run-of-the-river hydropower (w/o storage);Solar photovoltaic (PV) (general); | AI8: Capacity value (contribution to power adequacy);Curtailment;Direct costs (capital, O&M, etc.);Indirect costs (integration costs);Resource potential;Technical characteristics (efficiency, capacity factor, etc.) ; | AJ8: Additional ancillary/balancing services costs (economic);Curtailment cost (i.e., cost of handling excess electricity or negative prices);Grid management/contingency costs;Grid expansion or fortification needs;Reduced capacity factor of non-VRE;Short-term flexibility requirements; | AL8: Yes (but partly has to be with stored or firmed VRE) | AM8: Minimum share of non-VRE technologies (e.g., stabilizing share, firm capacity, etc.);Integration cost (economic/implicit);Integration requirements (technical/explicit, e.g., grid expansion and/or storage scale-up);Resource potential; | AO8: Curtailment of VRE;Demand response in transport (e.g., smart charging of EVs);Electricity storage;Electricity export/import (grid connection);Flexible electricity generation from thermal power (e.g., biomass, coal, gas) with or w/o CCS;Flexible electricity generation from hydropower;Power to hydrogen (electrolyzers); | AP8: Yes | AQ8: Short-term (hours to a few days);Long-term (months to seasons); | AR8: Storage is represented as a generic or homogenous asset w/o specific technology types.; | AS8: No | AU8: Capacity factor (max or nominal);Lifetime (in years);Power capacity (MW) (used for both charge and discharge);Round-trip efficiency; | AW8: Capital cost;Variable O&M cost;Fixed O&M cost;Replacement or major retrofit cost; | AX8: No (PCS and reservoir are treated with one cost value) | AY8: Energy-related (e.g., peak shaving);Power capacity-related (e.g., capacity firming);T&D grid (e.g., investment deferral);Renewable energy integration (e.g., curtailment reduction);Ancillary services (e.g., frequency regulation); | AZ8: At the generation side (central power plants);At the generation side (utility VRE);Power transmission level; | BA8: Energy-related services are modeled collectively.; | BB8: Capacity-related services are modeled collectively.; | BC8: Grid services are modeled collectively.; | BD8: Curtailment reduction;Integration cost reduction;Short-term flexibility/balancing (operative reserve);Capacity firming (increasing capacity value of VRE); | BF8: Cost competetiveness (incl. capital cost, O&M cost, levelized cost, etc.) compared to other alternatives;Rapid cost learning, i.e., the decline of storage cost in future;The increasing share of VRE in the system (e.g., as % of annual load or generation);The value of capacity services of storage;Barriers in the deployment of competing technologies (e.g., demand response, grid expansion, etc.);Considering the duration of storage services (short vs. long duration); | BH8: Storage can be deployed in competition with other alternatives, without any specific limit.;Storage is constrained by build-up, technological learning, and/or market-penetration growth rates (i.e., dynamic constraints dependent on storage deployment).; | BI8: Yes, storage can provide multiple services without any limits. | BJ8: Storage contributes to the system-level benefits. | BL8: No, storage parameters were kept consistently across scenarios. | BM8: N/A | BN8: Capacity of storage (GWh);Capital cost of storage technologies (EUR/GW or EUR/GWh);Efficiency of storage technologies (as % or lost energy (EJ/yr));Lifetime of storage technologies (year);Net electricity trade (import/export) (EJ/yr);Power capacity of electricity storage (GW);Power capacity of hydrogen electrolyzer (GW);
A9: 13 | B9: 45999.111 | C9: 45999.36 | D9: anonymous | G9: Shotaro Mori | H9: mori.shotaro.2n@kyoto-u.ac.jp | I9: Kyoto University | J9: Not participated in ECEMF; | K9: AIM | L9: Integrated assessement model soft-linked with energy system model | M9: Macro-economic modeling & Investment and capacity expansion planning | N9: Global | O9: EU divided in 2-3 subregions | P9: Coarse copperplate (multiple countries in one modeling node) | Q9: Not modeled | R9: Recursive dynamic (feedback loop) | S9: Yearly; | T9: ~2100 (full century) | U9: Representative time slices (sampled or clustered) | V9: In our model, intra-annual time is represented using representative time slices. The year is approximated by twelve representative days, one for each month, and each representative day is modeled with twenty-four hourly slices, so the time-slice length is one hour. In addition, the model includes four extra representative days, one in each quarter, selected to reflect conditions when VRE output is at its lowest based on historical weather data from 2006 to 2015. | W9: No | X9: No, the concurrency is not preserved (e.g., due to sampling) | Y9: Short-term events are not represented or relevant. | AD9: Scale-free technology types (e.g., different gas power plant types aggregated separately) | AE9: Buildings;Fossil fuel supply ;Heat supply (including district heating/cooling);Industry sector;Renewable-based fuels and derivatives (e.g., green hydrogen);Power (supply) sector;Transport sector; | AF9: Demand is modeled endogenously | AH9: Solar photovoltaic (PV) (rooftop);Solar photovoltaic (PV) (utility);Offshore wind;Onshore wind;Concentrated solar power (CSP) (w/o storage); | AI9: Capacity value (contribution to power adequacy);Curtailment;Resource potential;Technical characteristics (efficiency, capacity factor, etc.) ;Weather dependency (varying output in different time scales within a year);Direct costs (capital, O&M, etc.); | AJ9: Short-term flexibility requirements;Storage requirements for energy time-shifting; | AK9: The power sector uses a dispatch module with a 1 hour temporal resolution for representative days. The operating conditions of the power generator are determined under a cost-minimizing framework subject to satisfying the power supply–demand balance. Therefore, the capacity factor of flexible generators, storage requirements and other flexibility requirements (e.g., demand response) are determined endogenously in this model. | AL9: Yes (no need for generation from non-VRE or discharge from storage) | AM9: Integration requirements (technical/explicit, e.g., grid expansion and/or storage scale-up);Resource potential;Temporal or spatial mismatch between VRE and load; | AO9: Curtailment of VRE;Demand response in buildings;Demand response in transport (e.g., smart charging of EVs);Electricity storage;Flexible electricity generation from thermal power (e.g., biomass, coal, gas) with or w/o CCS;Power to hydrogen (electrolyzers);Power to synfuels (other than hydrogen); | AP9: Yes | AQ9: Long-term (months to seasons);Short-term (hours to a few days); | AR9: Pumped hydro storage;Secondary electorchemical batteries (e.g., Li-ion, etc.);Compressed air-based technologies; | AS9: No | AU9: Power capacity (MW) (used for both charge and discharge);Duration of discharge or energy-to-power ratio (h);Round-trip efficiency;Storage reservoir size (MWh);Lifetime (in years); | AW9: Capital cost;Fixed O&M cost; | AX9: No (PCS and reservoir are treated with one cost value) | AY9: Energy-related (e.g., peak shaving);Power capacity-related (e.g., capacity firming);Renewable energy integration (e.g., curtailment reduction); | AZ9: Storage is represented generically (no location specific); | BA9: Energy time shifting (arbitrage);Peak shaving (e.g., daily, seasonal);Energy-related services are modeled collectively.; | BB9: Back-up capacity (once or a few times a year);Capacity firming of non-VRE (e.g., day/night smoothing of nuclear power);Capacity-related services are modeled collectively.; | BC9: Investment in storage has no impact on T&D.; | BD9: VRE-related services of storage are modeled in an aggregated way (i.e., no individual representation of services).;Curtailment reduction;Energy time-shifting;Short-term flexibility/balancing (operative reserve);Capacity firming (increasing capacity value of VRE); | BE9: Potentially, energy storage in our model could provide the services ticked in Q.44, Q.45, and Q.47, however, these are not modeled as explicit, disaggregated services. Rather, in our model, energy storage is represented only as a device that can charge and discharge energy within the optimization of power system operation, and it is only ex post that storage is interpreted as having provided such services. | BF9: Cost competetiveness (incl. capital cost, O&M cost, levelized cost, etc.) compared to other alternatives;Considering the duration of storage services (short vs. long duration);Rapid cost learning, i.e., the decline of storage cost in future;The increasing share of VRE in the system (e.g., as % of annual load or generation);The value of capacity services of storage;Barriers in the deployment of competing technologies (e.g., demand response, grid expansion, etc.);Increased volatility in the pattern of electric load within a year;Increased variability in the pattern of VRE within a year; | BH9: (Some or all) storage technologies are constrained by available sites, resource potential, material availability, etc. (i.e., static constraints not necessarily dependent on storage deployment); | BI9: Yes, storage can provide multiple services without any limits. | BJ9: Storage contributes to the system-level benefits. | BL9: No, storage parameters were kept consistently across scenarios. | BM9: In our model, the techno-economic parameters of storage technologies are basically kept identical across scenarios. | BN9: Not participated in ECEMF;
A10: 14 | B10: 46013.77 | C10: 46013.842 | D10: anonymous | G10: Matthew Binsted | H10: matthew.binsted@pnnl.gov | I10: Pacific Northwest National Laboratory | J10: unsure (not involved in ECEMF); | K10: Global Change Analysis Model (GCAM) | L10: Integrated assessment model | M10: Market simulation | N10: Global | O10: EU divided in 2-3 subregions | P10: Coarse copperplate (multiple countries in one modeling node) | Q10: Not modeled | R10: Recursive dynamic (feedback loop) | S10: 2- to 5-yearly; | T10: ~2100 (full century) | U10: Yearly (No sub-annual time slices) | Y10: Short-term events are not represented or relevant. | AD10: Scale-free technology types (e.g., different gas power plant types aggregated separately) | AE10: Buildings;Fossil fuel supply ;Heat supply (including district heating/cooling);Industry sector;Renewable-based fuels and derivatives (e.g., green hydrogen);Power (supply) sector;Transport sector; | AF10: Demand is modeled endogenously | AH10: Concentrated solar power (CSP) (w/o storage);Onshore wind;Offshore wind;Solar photovoltaic (PV) (rooftop);Solar photovoltaic (PV) (utility); | AI10: Direct costs (capital, O&M, etc.);Indirect costs (integration costs);Resource potential;Technical characteristics (efficiency, capacity factor, etc.) ; | AJ10: GCAM v7.3+ represents diminishing VRE value with increasing VRE generation share - reflective of a variety of system costs needed to support VRE integration (VRE curtailment, additional firm capacity, transmission expansion, ancillary/balancing services costs, etc.). This value reduction is represented as a single integration cost added to other technology costs (capital, O&M, grid connection, etc.).;Additional ancillary/balancing services costs (economic);Curtailment cost (i.e., cost of handling excess electricity or negative prices);Grid expansion or fortification needs;Grid management/contingency costs; | AL10: Yes (but partly has to be with stored or firmed VRE) | AM10: Integration cost (economic/implicit);Resource potential; | AN10: GCAM v7.3+ represents diminishing VRE value with increasing VRE generation share - reflective of a variety of system costs needed to support VRE integration (VRE curtailment, additional firm capacity, transmission expansion, ancillary/balancing services costs, etc.). This value reduction is represented as a single integration cost added to other technology costs (capital, O&M, grid connection, etc.). This approach is documented at https://jgcri.github.io/gcam-doc/cmp/394-Intermittent_electricity_integration.pdf and is based on technology market share : value factor relationships from Mowers et al., 2023 (Mowers, M., Mignone, B.K. and Steinberg, D.C., 2023. Quantifying value and representing competitiveness of electricity system technologies in economic models. Applied Energy, 329, p.120132. https://doi.org/10.1016/j.apenergy.2022.120132.). | AO10: GCAM represents annual electricity generation by technology and does not explicitly balance electric loads subannually.; | AP10: Yes | AQ10: Short-term (hours to a few days);Storage duration does not play a role (e.g., storage is modeled generically); | AR10: Secondary electorchemical batteries (e.g., Li-ion, etc.);Storage is represented as a generic or homogenous asset w/o specific technology types.;In GCAM, storage is represented generically but parameterized based on a short-duration Li-ion battery system for PV and onshore wind and molten salt thermal storage for CSP.; | AS10: No | AU10: Lifetime (in years);Replacement (partial or full);Round-trip efficiency; | AW10: Capital cost;Variable O&M cost;Fixed O&M cost;Replacement or major retrofit cost; | AX10: No (PCS and reservoir are treated with one cost value) | AY10: Renewable energy integration (e.g., curtailment reduction); | AZ10: At the generation side (utility VRE); | BA10: Energy-related services are not relevant/modeled.; | BB10: Capacity-related services are modeled collectively.; | BC10: Not relevant; | BD10: Curtailment reduction;Integration cost reduction;VRE-related services of storage are modeled in an aggregated way (i.e., no individual representation of services).; | BE10: For variable renewable energy technologies (e.g., PV, CSP, onshore wind), GCAM represents two technology options: (1) VRE without dedicated storage which is subject to integration costs (reduced value factor with increasing market share) or (2) VRE with dedicated storage (short-duration Li-ion battery for PV and onshore wind; molten salt thermal storage for CSP) which entail additional capital and O&M costs and round trip energy losses but do not face any integration costs. | BF10: Cost competetiveness (incl. capital cost, O&M cost, levelized cost, etc.) compared to other alternatives;The increasing share of VRE in the system (e.g., as % of annual load or generation); | BH10: Storage capacity/activity is dependent to that of VRE (i.e., no VRE --> no storage).; | BI10: Not relevant | BJ10: Depending on the location of storage, it can be owned by the grid, energy utilites, or end user, and would benefit the respective owner. | BL10: Yes | BM10: I am not personally involved in ECEMF and am not aware of GCAM involvement. I answered Yes to question 49 since N/A was not an option. GCAM does include central, high, and low cost storage assumptions that can be used in different scenarios. | BN10: Not participated in ECEMF;

Sheet summary
A1: Metadata | B1: VRE | C1: Storage | D1: The name of the modeling tool for which you fill out the survey: | E1: AIM | F1: GCAM | G1: IMAGE | H1: MESSAGEix-GLOBIOM | I1: PROMETHEUS | J1: REMIND | K1: TIAM-ECN | L1: WITCH
D2: What is the main category of the model? | E2: Integrated assessement model soft-linked with energy system model | F2: Integrated assessment model | G2: Integrated assessment model | H2: Integrated assessment model | I2: Integrated assessment model | J2: Integrated assessment model | K2: Integrated assessment model | L2: Integrated assessment model
A3: 1 | D3: What option describes your modeling approach best? | E3: Macro-economic modeling & Investment and capacity expansion planning | F3: Market simulation | G3: Investment and capacity exapnsion planning | H3: Investment and capacity exapnsion planning | I3: Market simulation | J3: Hybrid: coupling an investment and capacity expansion energy system with a Ramsey growth model | K3: Investment and capacity exapnsion planning | L3: Macro-economic modeling
D4: What geographical scope presents your model best? | E4: Global | F4: Global | G4: Global | H4: Global | I4: Global | J4: Global | K4: Global | L4: Global
A5: 1 | D5: What is the spatial resolution of your model concerning the EU region? | E5: EU divided in 2-3 subregions | F5: EU divided in 2-3 subregions | G5: EU divided in 2-3 subregions | H5: EU divided in 2-3 subregions | I5: EU divided in 2-3 subregions | J5: Multiple-country (~1-4 EU countries in each model region) | K5: EU divided in 2-3 subregions | L5: EU- or European level (one model region)
A6: 1 | D6: What level(s) of the electricity network is represented in your model? | E6: Coarse copperplate (multiple countries in one modeling node) | F6: Coarse copperplate (multiple countries in one modeling node) | G6: Coarse copperplate (multiple countries in one modeling node) | H6: Coarse copperplate (multiple countries in one modeling node) | I6: Coarse copperplate (multiple countries in one modeling node) | J6: Coarse copperplate (multiple countries in one modeling node) | K6: Coarse copperplate (multiple countries in one modeling node) | L6: Coarse copperplate (multiple countries in one modeling node)
A7: 1 | D7: How are cross-border transmission lines between EU countries represented in your model? | E7: Not modeled | F7: Not modeled | G7: Using proxies or stylized methods | H7: Using proxies or stylized methods | I7: Not modeled | J7: not explicitly modeled, but generalized transmission expansion and pooling effects across EU regions are included | K7: cross-border lines are modelled between two subregions of EU (EastEU and WestEU) through an aggregated proxy. | L7: Not modeled
A8: 1 | D8: How the planning foresight is treated in your model: | E8: Recursive dynamic (feedback loop) | F8: Recursive dynamic (feedback loop) | G8: Recursive dynamic (feedback loop) | H8: Perfect foresight | I8: Myopic foresight (short sighted) | J8: Perfect foresight | K8: Perfect foresight | L8: Perfect foresight
D9: What time intervals are considered in the model horizon? (Please tick all that apply) | E9: Yearly; | F9: 2- to 5-yearly; | G9: Yearly; | H9: 2- to 5-yearly;10-yearly and/or longer; | I9: Yearly; | J9: 2- to 5-yearly; | K9: 2- to 5-yearly;10-yearly and/or longer; | L9: 2- to 5-yearly;
D10: What planning/modeling horizon is used in your analysis? | E10: ~2100 (full century) | F10: ~2100 (full century) | G10: ~2100 (full century) | H10: ~2100 (full century) | I10: ~2050 (mid century) | J10: ~2100 (full century) | K10: ~2100 (full century) | L10: ~2100 (full century)
A11: 1 | D11: How is the sub-annual temporal resolution represented in your model? | E11: Representative time slices (sampled or clustered) | F11: Yearly (No sub-annual time slices) | G11: Multi-hourly | H11: Yearly (No sub-annual time slices) | I11: Yearly (No sub-annual time slices) | J11: Not explicitly, but the effects on VRE integration/storage/transmission build-out are represented in an aggregate way | K11: Seasonal (2-4 time slices per model period) | L11: Yearly (No sub-annual time slices)
D12: If you answered "Representative time slices" or "Other", please explain. For example, the method of sampling/clustering and/or the length of time slices. | E12: In our model, intra-annual time is represented using representative time slices. The year is approximated by twelve representative days, one for each month, and each representative day is modeled with twenty-four hourly slices, so the time-slice length is one hour. In addition, the model includes four extra representative days, one in each quarter, selected to reflect conditions when VRE output is at its lowest based on historical weather data from 2006 to 2015. | J12: Not explicitly, but the effects on VRE integration/storage/transmission build-out are represented in an aggregate way, parameterized to reflect results from more detailed (hourly) models
A13: 1 | D13: Is the chronology of (sub-annual) time slices preserved in your modeling work? | E13: No | G13: No | J13: Other | K13: No
A14: 1 | D14: Is the joint variability of supply and demand resources in each sub-annual time slice captured in your model? This means, e.g., the timeseries of wind, solar PV, and demand are all concurrent with... | E14: No, the concurrency is not preserved (e.g., due to sampling) | G14: Yes, although the demand pattern is historic and not based on endogenous demand sector developments | J14: Not relevant (e.g., no temporal representation) | K14: Not relevant (e.g., no temporal representation)
A15: 1 | D15: How are short-term operational events represented in your model? Short-term decisions are in the scale of hours to a few days including generator scheduling, ramping rates, flexibility requirement... | E15: Short-term events are not represented or relevant. | F15: Short-term events are not represented or relevant. | G15: A few extreme short-term events are represented explicitly (e.g., seasonal peak load and zero supply from renewables). | H15: Short-term events are represented implicitly, e.g., as a cost or other proxy. | I15: Short-term events are represented implicitly, e.g., as a cost or other proxy. | J15: Short-term events are represented implicitly, e.g., as a cost or other proxy. | K15: Only for solar and wind generation, we represent short-term events implicitly as an additional flexibility requirement costs. | L15: Short-term events are represented implicitly, e.g., as a cost or other proxy.
A16: 1 | D16: If short-term decisions are not represented explicitly in your model, how is the relevant parametrization done? Check all relevant answers. | G16: Using data from various empirical or model-based studies;We use the RLDC dataset developed by PIK during the ADVANCE project (Ueckerdt et al., 2016); | H16: Using data from various empirical or model-based studies;Using data from a detailed operational and dispatch model (unidirectional soft-linking); | I16: Using data from various empirical or model-based studies; | J16: Using data from various empirical or model-based studies; | K16: Bidirectional soft-linking to a detailed operational and dispatch model;Using data from various empirical or model-based studies;We are doing a bidirectional soft-linking with a detailed power system model in WP3.2. It is a work in progress.. ; | L16: Using data from various empirical or model-based studies;
A17: 1 | D17: How are short-term decisions linked to long-term infrastructure planning and investment decisions in your model? Long-term decisions refer to multi-decadal decisions such as investment in power pl... | G17: Short-term decisions are represented using proxies and/or in a stylized format as part of long-term decisionmaking | H17: Short-term decisions are represented using proxies and/or in a stylized format as part of long-term decisionmaking | I17: Short-term decisions are represented using proxies and/or in a stylized format as part of long-term decisionmaking | J17: Short-term decisions are represented using proxies and/or in a stylized format as part of long-term decisionmaking | K17: Short- and long-term decisions are co-optimized in an integrated way. | L17: Short-term decisions are not relevant to the modeling scope.
A18: 1 | D18: Is the weather uncertainty in multiple years included in your model parameters? | G18: Data of one representative year based on irradiation and wind speed data for 1984–2005 | H18: Applying peak load factors to cover grid contingencies and uncertainties in load | I18: Yes, using varying input data (or sensitivity analysis) | J18: No | K18: No | L18: No
D19: What future uncertainties are considered when representing sub-annual temporal variability in your model parameters? Here, we refer to those events not driven by socioeconomic developments or cost... | G19: None of the above or not relevant; | H19: None of the above or not relevant; | I19: Climate impact on the supply side;Climate impact on the demand side; | J19: None of the above or not relevant; | K19: None of the above or not relevant; | L19: Climate impact on the supply side;Climate impact on the demand side;
D20: What is the level of granularity in representing technologies in your model? | E20: Scale-free technology types (e.g., different gas power plant types aggregated separately) | F20: Scale-free technology types (e.g., different gas power plant types aggregated separately) | G20: Scale-free technology types (e.g., different gas power plant types aggregated separately) | H20: Scale-free technology types (e.g., different gas power plant types aggregated separately) | I20: Technologies by input fuel type (e.g., all gas power plant types aggregated together) | J20: Scale-free technology types (e.g., different gas power plant types aggregated separately) | K20: Scale-free technology types (e.g., different gas power plant types aggregated separately) | L20: Technologies by input fuel type (e.g., all gas power plant types aggregated together)
